Workbook
Name Clientes: Clientes!$A$3:$A$643
Name Grupos: 'Datos Maestros'!$K$2:$K$65
Name ListaProductos: Precios!$B$2:$B$836
Name Negocios: 'Datos Maestros'!$P$2:$P$14
Name NombreProductos: 'Productos - Inventario'!$A$1:$A$130
Name Pesos: 'Datos Maestros'!$H$2:$H$9
Name Productos: 'Datos Maestros'!$J$2:$J$65
Name ProductosInventario: 'Productos - Inventario'!$A$2:$A$130
Name Proveedores: 'Datos Maestros'!$A$2:$A$17
Name StatusEntrega: 'Datos Maestros'!$R$2:$R$15
Name StatusPago: 'Datos Maestros'!$T$2:$T$16
Name Unidades: 'Datos Maestros'!$F$2:$F$7
Name Vendedores: 'Datos Maestros'!$C$2:$C$23

Sheet Estructura
A1: Estructura | C1: Datos
A2: DROP TABLE DETALLES_DOCUMENTO CASCADE CONSTRAINTS; | C2: TRUNCATE TABLE DETALLES_DOCUMENTO;
A3: DROP TABLE DOCUMENTOS CASCADE CONSTRAINTS; | C3: TRUNCATE TABLE DOCUMENTOS;
A4: DROP TABLE CLIENTES CASCADE CONSTRAINTS; | C4: TRUNCATE TABLE CLIENTES;
A5: DROP TABLE EMPLEADOS CASCADE CONSTRAINTS; | C5: TRUNCATE TABLE EMPLEADOS;
A6: DROP TABLE PRECIOS CASCADE CONSTRAINTS; | C6: TRUNCATE TABLE PRECIOS;
A7: DROP TABLE PRODUCTOS CASCADE CONSTRAINTS; | C7: TRUNCATE TABLE PRODUCTOS;
A8: DROP TABLE COMUNAS CASCADE CONSTRAINTS; | C8: TRUNCATE TABLE COMUNAS;
A9: DROP TABLE REGIONES CASCADE CONSTRAINTS; | C9: TRUNCATE TABLE REGIONES;
A10: DROP TABLE TIPOS_DOCUMENTO CASCADE CONSTRAINTS; | C10: TRUNCATE TABLE TIPOS_DOCUMENTO;

Sheet REGIONES
A1: Id_Region | B1: Nombre | C1: Script
A2: 1 | B2: Región de Tarapacá | C2: =CONCATENATE("INSERT INTO REGIONES (ID_REGION, NOMBRE) VALUES (",A2,",","'",B2,"');") -> INSERT INTO REGIONES (ID_REGION, NOMBRE) VALUES (1,'Región de Tarapacá');
A3: 2 | B3: Región de Antofagasta | C3: =CONCATENATE("INSERT INTO REGIONES (ID_REGION, NOMBRE) VALUES (",A3,",","'",B3,"');") -> INSERT INTO REGIONES (ID_REGION, NOMBRE) VALUES (2,'Región de Antofagasta');
A4: 3 | B4: Región de Atacama | C4: =CONCATENATE("INSERT INTO REGIONES (ID_REGION, NOMBRE) VALUES (",A4,",","'",B4,"');") -> INSERT INTO REGIONES (ID_REGION, NOMBRE) VALUES (3,'Región de Atacama');
A5: 4 | B5: Región de Coquimbo | C5: =CONCATENATE("INSERT INTO REGIONES (ID_REGION, NOMBRE) VALUES (",A5,",","'",B5,"');") -> INSERT INTO REGIONES (ID_REGION, NOMBRE) VALUES (4,'Región de Coquimbo');
A6: 5 | B6: Región de Valparaíso | C6: =CONCATENATE("INSERT INTO REGIONES (ID_REGION, NOMBRE) VALUES (",A6,",","'",B6,"');") -> INSERT INTO REGIONES (ID_REGION, NOMBRE) VALUES (5,'Región de Valparaíso');
A7: 6 | B7: Región del Libertador General Bernardo OHiggins | C7: =CONCATENATE("INSERT INTO REGIONES (ID_REGION, NOMBRE) VALUES (",A7,",","'",B7,"');") -> INSERT INTO REGIONES (ID_REGION, NOMBRE) VALUES (6,'Región del Libertador General Bernardo OHiggins');
A8: 7 | B8: Región del Maule | C8: =CONCATENATE("INSERT INTO REGIONES (ID_REGION, NOMBRE) VALUES (",A8,",","'",B8,"');") -> INSERT INTO REGIONES (ID_REGION, NOMBRE) VALUES (7,'Región del Maule');
A9: 8 | B9: Región del Biobío | C9: =CONCATENATE("INSERT INTO REGIONES (ID_REGION, NOMBRE) VALUES (",A9,",","'",B9,"');") -> INSERT INTO REGIONES (ID_REGION, NOMBRE) VALUES (8,'Región del Biobío');
A10: 9 | B10: Región de La Araucanía | C10: =CONCATENATE("INSERT INTO REGIONES (ID_REGION, NOMBRE) VALUES (",A10,",","'",B10,"');") -> INSERT INTO REGIONES (ID_REGION, NOMBRE) VALUES (9,'Región de La Araucanía');
A11: 10 | B11: Región de Los Lagos | C11: =CONCATENATE("INSERT INTO REGIONES (ID_REGION, NOMBRE) VALUES (",A11,",","'",B11,"');") -> INSERT INTO REGIONES (ID_REGION, NOMBRE) VALUES (10,'Región de Los Lagos');
A12: 11 | B12: Región de Aysén del General Carlos Ibáñez del Campo | C12: =CONCATENATE("INSERT INTO REGIONES (ID_REGION, NOMBRE) VALUES (",A12,",","'",B12,"');") -> INSERT INTO REGIONES (ID_REGION, NOMBRE) VALUES (11,'Región de Aysén del General Carlos Ibáñez del Campo');
A13: 12 | B13: Región de Magallanes y de la Antártica Chilena | C13: =CONCATENATE("INSERT INTO REGIONES (ID_REGION, NOMBRE) VALUES (",A13,",","'",B13,"');") -> INSERT INTO REGIONES (ID_REGION, NOMBRE) VALUES (12,'Región de Magallanes y de la Antártica Chilena');
... A17: 16 | B17: Región de Ñuble | C17: =CONCATENATE("INSERT INTO REGIONES (ID_REGION, NOMBRE) VALUES (",A17,",","'",B17,"');") -> INSERT INTO REGIONES (ID_REGION, NOMBRE) VALUES (16,'Región de Ñuble ');
C18: COMMIT;

Sheet COMUNAS
A1: Id_Comuna | B1: Nombre | C1: Id_Region | D1: Script
A2: 1101 | B2: Iquique | C2: =IF(LEN(A2)=5, LEFT(A2,2),LEFT(A2,1)) -> 1 | D2: =CONCATENATE( "INSERT INTO COMUNAS (ID_COMUNA,NOMBRE,ID_REGION) VALUES (",A2,",'",B2,"',",C2,");") -> INSERT INTO COMUNAS (ID_COMUNA,NOMBRE,ID_REGION) VALUES (1101,'Iquique',1);
A3: 1107 | B3: Alto Hospicio | C3: =IF(LEN(A3)=5,LEFT(A3,2),LEFT(A3,1)) -> 1 | D3: =CONCATENATE( "INSERT INTO COMUNAS (ID_COMUNA,NOMBRE,ID_REGION) VALUES (",A3,",'",B3,"',",C3,");") -> INSERT INTO COMUNAS (ID_COMUNA,NOMBRE,ID_REGION) VALUES (1107,'Alto Hospicio',1);
A4: 1401 | B4: Pozo Almonte | C4: =IF(LEN(A4)=5,LEFT(A4,2),LEFT(A4,1)) -> 1 | D4: =CONCATENATE( "INSERT INTO COMUNAS (ID_COMUNA,NOMBRE,ID_REGION) VALUES (",A4,",'",B4,"',",C4,");") -> INSERT INTO COMUNAS (ID_COMUNA,NOMBRE,ID_REGION) VALUES (1401,'Pozo Almonte',1);
A5: 1402 | B5: Camiña | C5: =IF(LEN(A5)=5,LEFT(A5,2),LEFT(A5,1)) -> 1 | D5: =CONCATENATE( "INSERT INTO COMUNAS (ID_COMUNA,NOMBRE,ID_REGION) VALUES (",A5,",'",B5,"',",C5,");") -> INSERT INTO COMUNAS (ID_COMUNA,NOMBRE,ID_REGION) VALUES (1402,'Camiña',1);
A6: 1403 | B6: Colchane | C6: =IF(LEN(A6)=5,LEFT(A6,2),LEFT(A6,1)) -> 1 | D6: =CONCATENATE( "INSERT INTO COMUNAS (ID_COMUNA,NOMBRE,ID_REGION) VALUES (",A6,",'",B6,"',",C6,");") -> INSERT INTO COMUNAS (ID_COMUNA,NOMBRE,ID_REGION) VALUES (1403,'Colchane',1);
A7: 1404 | B7: Huara | C7: =IF(LEN(A7)=5,LEFT(A7,2),LEFT(A7,1)) -> 1 | D7: =CONCATENATE( "INSERT INTO COMUNAS (ID_COMUNA,NOMBRE,ID_REGION) VALUES (",A7,",'",B7,"',",C7,");") -> INSERT INTO COMUNAS (ID_COMUNA,NOMBRE,ID_REGION) VALUES (1404,'Huara',1);
A8: 1405 | B8: Pica | C8: =IF(LEN(A8)=5,LEFT(A8,2),LEFT(A8,1)) -> 1 | D8: =CONCATENATE( "INSERT INTO COMUNAS (ID_COMUNA,NOMBRE,ID_REGION) VALUES (",A8,",'",B8,"',",C8,");") -> INSERT INTO COMUNAS (ID_COMUNA,NOMBRE,ID_REGION) VALUES (1405,'Pica',1);
A9: 2101 | B9: Antofagasta | C9: =IF(LEN(A9)=5,LEFT(A9,2),LEFT(A9,1)) -> 2 | D9: =CONCATENATE( "INSERT INTO COMUNAS (ID_COMUNA,NOMBRE,ID_REGION) VALUES (",A9,",'",B9,"',",C9,");") -> INSERT INTO COMUNAS (ID_COMUNA,NOMBRE,ID_REGION) VALUES (2101,'Antofagasta',2);
A10: 2102 | B10: Mejillones | C10: =IF(LEN(A10)=5,LEFT(A10,2),LEFT(A10,1)) -> 2 | D10: =CONCATENATE( "INSERT INTO COMUNAS (ID_COMUNA,NOMBRE,ID_REGION) VALUES (",A10,",'",B10,"',",C10,");") -> INSERT INTO COMUNAS (ID_COMUNA,NOMBRE,ID_REGION) VALUES (2102,'Mejillones',2);
A11: 2103 | B11: Sierra Gorda | C11: =IF(LEN(A11)=5,LEFT(A11,2),LEFT(A11,1)) -> 2 | D11: =CONCATENATE( "INSERT INTO COMUNAS (ID_COMUNA,NOMBRE,ID_REGION) VALUES (",A11,",'",B11,"',",C11,");") -> INSERT INTO COMUNAS (ID_COMUNA,NOMBRE,ID_REGION) VALUES (2103,'Sierra Gorda',2);
A12: 2104 | B12: Taltal | C12: =IF(LEN(A12)=5,LEFT(A12,2),LEFT(A12,1)) -> 2 | D12: =CONCATENATE( "INSERT INTO COMUNAS (ID_COMUNA,NOMBRE,ID_REGION) VALUES (",A12,",'",B12,"',",C12,");") -> INSERT INTO COMUNAS (ID_COMUNA,NOMBRE,ID_REGION) VALUES (2104,'Taltal',2);
A13: 2201 | B13: Calama | C13: =IF(LEN(A13)=5,LEFT(A13,2),LEFT(A13,1)) -> 2 | D13: =CONCATENATE( "INSERT INTO COMUNAS (ID_COMUNA,NOMBRE,ID_REGION) VALUES (",A13,",'",B13,"',",C13,");") -> INSERT INTO COMUNAS (ID_COMUNA,NOMBRE,ID_REGION) VALUES (2201,'Calama',2);
A14: 2202 | B14: Ollague | C14: =IF(LEN(A14)=5,LEFT(A14,2),LEFT(A14,1)) -> 2 | D14: =CONCATENATE( "INSERT INTO COMUNAS (ID_COMUNA,NOMBRE,ID_REGION) VALUES (",A14,",'",B14,"',",C14,");") -> INSERT INTO COMUNAS (ID_COMUNA,NOMBRE,ID_REGION) VALUES (2202,'Ollague',2);
... A346: 15202 | B346: General Lagos | C346: =IF(LEN(A346)=5,LEFT(A346,2),LEFT(A346,1)) -> 15 | D346: =CONCATENATE( "INSERT INTO COMUNAS (ID_COMUNA,NOMBRE,ID_REGION) VALUES (",A346,",'",B346,"',",C346,");") -> INSERT INTO COMUNAS (ID_COMUNA,NOMBRE,ID_REGION) VALUES (15202,'General Lagos',15);
D347: COMMIT;

Sheet TIPOS_DOCUMENTO
A1: Id_Tipo | B1: Descripcion | C1: Script
A2: 1 | B2: Boleta de Venta | C2: =CONCATENATE("INSERT INTO TIPOS_DOCUMENTO(ID_TIPO,DESCRIPCION) VALUES(",A2,",'",B2,"');") -> INSERT INTO TIPOS_DOCUMENTO(ID_TIPO,DESCRIPCION) VALUES(1,'Boleta de Venta');
A3: 2 | B3: Factura de Venta | C3: =CONCATENATE("INSERT INTO TIPOS_DOCUMENTO(ID_TIPO,DESCRIPCION) VALUES(",A3,",'",B3,"');") -> INSERT INTO TIPOS_DOCUMENTO(ID_TIPO,DESCRIPCION) VALUES(2,'Factura de Venta');
A4: 3 | B4: Nota de Crédito | C4: =CONCATENATE("INSERT INTO TIPOS_DOCUMENTO(ID_TIPO,DESCRIPCION) VALUES(",A4,",'",B4,"');") -> INSERT INTO TIPOS_DOCUMENTO(ID_TIPO,DESCRIPCION) VALUES(3,'Nota de Crédito');
C5: COMMIT;

Sheet EMPLEADOS
A1: Rut_Empleado | B1: Primer_Nombre | C1: Segundo_Nombre | D1: Apellido_Paterno | E1: Apellido_Materno | F1: Direccion | G1: Correo | H1: Fecha_Nacimiento | I1: Id_Comuna | J1: Id_Region | K1: Script
A2: 14526149-K | B2: Fernando | C2: Amaro | D2: Figueroa | E2: Aguirre | F2: Avenida Departamental 111 | G2: Fernando.Figueroa@cayrap.cl | H2: 05-07-1981 | I2: 13110 | J2: 13 | K2: =CONCATENATE("INSERT INTO EMPLEADOS (RUT_EMPLEADO, PRIMER_NOMBRE, SEGUNDO_NOMBRE, APELLIDO_PATERNO, APELLIDO_MATERNO, DIRECCION, CORREO, FECHA_NACIMIENTO, ID_COMUNA, ID_REGION) VALUES (","'",A2,"','",B2,"','",C2,"','",D2,"','",E2,"','",F2,"','",G2,"',","TO_DATE('",H2,"','DD/MM/YYYY'),",I2,",",J2,");") -> INSERT INTO EMPLEADOS (RUT_EMPLEADO, PRIMER_NOMBRE, SEGUNDO_NOMBRE, APELLIDO_PATERNO, APELLIDO_MATERNO, DIRECCION, CORREO, FECHA_NACIMIENTO, ID_COMUNA, ID_REGION) VALUES ('14526149-K','Fernando','Amaro','Figueroa','Aguirre','Avenida Departamental 111','Fernando.Figueroa@cayrap.cl',TO_DATE('05-07-1981','DD/MM/YYYY'),13110,13);
A3: 17866360-7 | B3: Amalia | C3: Elena | D3: Herrera | E3: Santelices | F3: Calle Nonato Coo 345 | G3: Amalia.Herrera@cayrap.cl | H3: 24-02-1992 | I3: 13201 | J3: 13 | K3: =CONCATENATE("INSERT INTO EMPLEADOS (RUT_EMPLEADO, PRIMER_NOMBRE, SEGUNDO_NOMBRE, APELLIDO_PATERNO, APELLIDO_MATERNO, DIRECCION, CORREO, FECHA_NACIMIENTO, ID_COMUNA, ID_REGION) VALUES (","'",A3,"','",B3,"','",C3,"','",D3,"','",E3,"','",F3,"','",G3,"',","TO_DATE('",H3,"','DD/MM/YYYY'),",I3,",",J3,");") -> INSERT INTO EMPLEADOS (RUT_EMPLEADO, PRIMER_NOMBRE, SEGUNDO_NOMBRE, APELLIDO_PATERNO, APELLIDO_MATERNO, DIRECCION, CORREO, FECHA_NACIMIENTO, ID_COMUNA, ID_REGION) VALUES ('17866360-7','Amalia','Elena','Herrera','Santelices','Calle Nonato Coo 345','Amalia.Herrera@cayrap.cl',TO_DATE('24-02-1992','DD/MM/YYYY'),13201,13);
A4: 19145461-8 | B4: Camila | C4: Andrea | D4: Herrera | E4: Parra | F4: Los Plátanos 3130 | G4: Camila.Herrera@cayrap.cl | H4: 17-04-1996 | I4: 13118 | J4: 13 | K4: =CONCATENATE("INSERT INTO EMPLEADOS (RUT_EMPLEADO, PRIMER_NOMBRE, SEGUNDO_NOMBRE, APELLIDO_PATERNO, APELLIDO_MATERNO, DIRECCION, CORREO, FECHA_NACIMIENTO, ID_COMUNA, ID_REGION) VALUES (","'",A4,"','",B4,"','",C4,"','",D4,"','",E4,"','",F4,"','",G4,"',","TO_DATE('",H4,"','DD/MM/YYYY'),",I4,",",J4,");") -> INSERT INTO EMPLEADOS (RUT_EMPLEADO, PRIMER_NOMBRE, SEGUNDO_NOMBRE, APELLIDO_PATERNO, APELLIDO_MATERNO, DIRECCION, CORREO, FECHA_NACIMIENTO, ID_COMUNA, ID_REGION) VALUES ('19145461-8','Camila','Andrea','Herrera','Parra','Los Plátanos 3130','Camila.Herrera@cayrap.cl',TO_DATE('17-04-1996','DD/MM/YYYY'),13118,13);
A5: 11383327-0 | B5: Claudia | C5: Alejandra | D5: Herrera | E5: Nuñez | F5: Avenida Concha y Toro 3452 | G5: Claudia.Herrera@cayrap.cl | H5: 07-04-1969 | I5: 13201 | J5: 13 | K5: =CONCATENATE("INSERT INTO EMPLEADOS (RUT_EMPLEADO, PRIMER_NOMBRE, SEGUNDO_NOMBRE, APELLIDO_PATERNO, APELLIDO_MATERNO, DIRECCION, CORREO, FECHA_NACIMIENTO, ID_COMUNA, ID_REGION) VALUES (","'",A5,"','",B5,"','",C5,"','",D5,"','",E5,"','",F5,"','",G5,"',","TO_DATE('",H5,"','DD/MM/YYYY'),",I5,",",J5,");") -> INSERT INTO EMPLEADOS (RUT_EMPLEADO, PRIMER_NOMBRE, SEGUNDO_NOMBRE, APELLIDO_PATERNO, APELLIDO_MATERNO, DIRECCION, CORREO, FECHA_NACIMIENTO, ID_COMUNA, ID_REGION) VALUES ('11383327-0','Claudia','Alejandra','Herrera','Nuñez','Avenida Concha y Toro 3452','Claudia.Herrera@cayrap.cl',TO_DATE('07-04-1969','DD/MM/YYYY'),13201,13);
A6: 10554261-5 | B6: Juan | C6: Carlos | D6: Herrera | E6: Fernandez | F6: Diagonal Santa Irene 3015 | G6: Juan.Herrera@cayrap.cl | H6: 11-09-1968 | I6: 13110 | J6: 13 | K6: =CONCATENATE("INSERT INTO EMPLEADOS (RUT_EMPLEADO, PRIMER_NOMBRE, SEGUNDO_NOMBRE, APELLIDO_PATERNO, APELLIDO_MATERNO, DIRECCION, CORREO, FECHA_NACIMIENTO, ID_COMUNA, ID_REGION) VALUES (","'",A6,"','",B6,"','",C6,"','",D6,"','",E6,"','",F6,"','",G6,"',","TO_DATE('",H6,"','DD/MM/YYYY'),",I6,",",J6,");") -> INSERT INTO EMPLEADOS (RUT_EMPLEADO, PRIMER_NOMBRE, SEGUNDO_NOMBRE, APELLIDO_PATERNO, APELLIDO_MATERNO, DIRECCION, CORREO, FECHA_NACIMIENTO, ID_COMUNA, ID_REGION) VALUES ('10554261-5','Juan','Carlos','Herrera','Fernandez','Diagonal Santa Irene 3015','Juan.Herrera@cayrap.cl',TO_DATE('11-09-1968','DD/MM/YYYY'),13110,13);
A7: 13748252-5 | B7: Soledad | C7: Ester | D7: Saavedra | E7: Gonzalez | F7: Avenida Santa Rosa 2606 | G7: Soledad.Saavedra@cayrap.cl | H7: 11-08-1974 | I7: 13129 | J7: 13 | K7: =CONCATENATE("INSERT INTO EMPLEADOS (RUT_EMPLEADO, PRIMER_NOMBRE, SEGUNDO_NOMBRE, APELLIDO_PATERNO, APELLIDO_MATERNO, DIRECCION, CORREO, FECHA_NACIMIENTO, ID_COMUNA, ID_REGION) VALUES (","'",A7,"','",B7,"','",C7,"','",D7,"','",E7,"','",F7,"','",G7,"',","TO_DATE('",H7,"','DD/MM/YYYY'),",I7,",",J7,");") -> INSERT INTO EMPLEADOS (RUT_EMPLEADO, PRIMER_NOMBRE, SEGUNDO_NOMBRE, APELLIDO_PATERNO, APELLIDO_MATERNO, DIRECCION, CORREO, FECHA_NACIMIENTO, ID_COMUNA, ID_REGION) VALUES ('13748252-5','Soledad','Ester','Saavedra','Gonzalez','Avenida Santa Rosa 2606','Soledad.Saavedra@cayrap.cl',TO_DATE('11-08-1974','DD/MM/YYYY'),13129,13);
K8: COMMIT;

Sheet CLIENTES_BD
D1: Elementos a Considerar
D2: En la empresa CayRAP, los clientes que tienen rut son EMPRESAS y si no tiene rut es persona natural, por lo tanto ,no sirve la actual PK de la tabla CLIENTES. Es por ello que se realizaran lo siguientes ajustes en el Modelo | I2: Script
D3: 1) | E3: Borrar la relación (FK) con la tabla DOCUMENTOS | I3: ALTER TABLE DOCUMENTOS DROP CONSTRAINT CLIENTE_FK_DOCUMENTO;
D4: 2) | E4: Eliminar actual PK de la tabla CLIENTES | I4: ALTER TABLE CLIENTES DROP PRIMARY KEY;
D5: 3) | E5: Crear el campo ID_CLIENTE en la tabla CLIENTES | I5: ALTER TABLE CLIENTES ADD ID_CLIENTE NUMBER(10) GENERATED ALWAYS AS IDENTITY MINVALUE 1 MAXVALUE 9999999999;
D6: 4) | E6: Ajustar el atributo RUT_CLIENTE para que sea opcional | I6: ALTER TABLE CLIENTES MODIFY RUT_CLIENTE VARCHAR2(15) NULL;
D7: 5) | E7: Eliminar el campo RUT_CLIENTE de la tabla DOCUMENTOS | I7: ALTER TABLE DOCUMENTOS DROP COLUMN RUT_CLIENTE ;
D8: 6) | E8: Crear el campo ID_CLIENTE en la tabla DOCUMENTOS | I8: ALTER TABLE DOCUMENTOS ADD ID_CLIENTE NUMBER(10) NOT NULL;
D9: 7) | E9: Utilizar el campo ID_CLIENTE como PK de la tabla CLIENTES | I9: ALTER TABLE CLIENTES ADD PRIMARY KEY (ID_CLIENTE);
D10: 8) | E10: Crear la relacion(FK) con la tabla DOCUMENTOS | I10: ALTER TABLE DOCUMENTOS ADD CONSTRAINT CLIENTE_FK_DOCUMENTO FOREIGN KEY (ID_CLIENTE) REFERENCES CLIENTES (ID_CLIENTE);
D11: 9) | E11: Crear los registros en la tabla CLIENTES | I11: Ejecutar script de creación de registros
B16: Asignacion Automatica
A17: Cliente | B17: Id_Cliente | C17: Rut_Cliente | D17: Razon_Social | E17: Direccion | F17: Id_Comuna | G17: Id_Region | H17: Fecha_Nacimiento | I17: Script
A18: =Clientes!A3 -> Abuelita Lorenzo | B18: 1 | C18: =IF(ISBLANK(Clientes!L3),"NULL",CONCATENATE("'",Clientes!L3,"'")) -> NULL | D18: =CONCATENATE("'",Clientes!A3,"'") -> 'Abuelita Lorenzo' | E18: =IF(ISBLANK(Clientes!C3),"'Sin Direccion'",CONCATENATE("'",MID(Clientes!C3,1,95),"'")) -> 'Marcela Paz 8334' | F18: 13101 | G18: 13 | H18: 29-11-1967 | I18: =CONCATENATE("INSERT INTO CLIENTES(RUT_CLIENTE,RAZON_SOCIAL,DIRECCION,ID_COMUNA,ID_REGION,FECHA_NACIMIENTO) VALUES (",C18,",",D18,",",E18,",",F18,",",G18,",","TO_DATE('",H18,"','DD-MM-YYYY'));") -> INSERT INTO CLIENTES(RUT_CLIENTE,RAZON_SOCIAL,DIRECCION,ID_COMUNA,ID_REGION,FECHA_NACIMIENTO) VALUES (NULL,'Abuelita Lorenzo','Marcela Paz 8334',13101,13,TO_DATE('29-11-1967','DD-MM-YYYY'));
A19: =Clientes!A4 -> Elizabeth Leyton | B19: =B18+1 -> 2 | C19: =IF(ISBLANK(Clientes!L4),"NULL",CONCATENATE("'",Clientes!L4,"'")) -> NULL | D19: =CONCATENATE("'",Clientes!A4,"'") -> 'Elizabeth Leyton' | E19: =IF(ISBLANK(Clientes!C4),"'Sin Direccion'",CONCATENATE("'",MID(Clientes!C4,1,95),"'")) -> 'San Vicente de Paul 8186 la florida jardín alto' | F19: 13102 | G19: 13 | H19: 29-11-1967 | I19: =CONCATENATE("INSERT INTO CLIENTES(RUT_CLIENTE,RAZON_SOCIAL,DIRECCION,ID_COMUNA,ID_REGION,FECHA_NACIMIENTO) VALUES (",C19,",",D19,",",E19,",",F19,",",G19,",","TO_DATE('",H19,"','DD-MM-YYYY'));") -> INSERT INTO CLIENTES(RUT_CLIENTE,RAZON_SOCIAL,DIRECCION,ID_COMUNA,ID_REGION,FECHA_NACIMIENTO) VALUES (NULL,'Elizabeth Leyton','San Vicente de Paul 8186 la florida jardín alto',13102,13,TO_DATE('29-11-1967','DD-MM-YYYY'));
A20: =Clientes!A5 -> Marcelo Clerc | B20: =B19+1 -> 3 | C20: =IF(ISBLANK(Clientes!L5),"NULL",CONCATENATE("'",Clientes!L5,"'")) -> NULL | D20: =CONCATENATE("'",Clientes!A5,"'") -> 'Marcelo Clerc' | E20: =IF(ISBLANK(Clientes!C5),"'Sin Direccion'",CONCATENATE("'",MID(Clientes!C5,1,95),"'")) -> 'Rungue 8615 / Doblar en Santa Julia a mano derecha' | F20: 13103 | G20: 13 | H20: 29-11-1967 | I20: =CONCATENATE("INSERT INTO CLIENTES(RUT_CLIENTE,RAZON_SOCIAL,DIRECCION,ID_COMUNA,ID_REGION,FECHA_NACIMIENTO) VALUES (",C20,",",D20,",",E20,",",F20,",",G20,",","TO_DATE('",H20,"','DD-MM-YYYY'));") -> INSERT INTO CLIENTES(RUT_CLIENTE,RAZON_SOCIAL,DIRECCION,ID_COMUNA,ID_REGION,FECHA_NACIMIENTO) VALUES (NULL,'Marcelo Clerc','Rungue 8615 / Doblar en Santa Julia a mano derecha',13103,13,TO_DATE('29-11-1967','DD-MM-YYYY'));
A21: =Clientes!A6 -> Lorena - Quilpolemu 7170 | B21: =B20+1 -> 4 | C21: =IF(ISBLANK(Clientes!L6),"NULL",CONCATENATE("'",Clientes!L6,"'")) -> NULL | D21: =CONCATENATE("'",Clientes!A6,"'") -> 'Lorena - Quilpolemu 7170' | E21: =IF(ISBLANK(Clientes!C6),"'Sin Direccion'",CONCATENATE("'",MID(Clientes!C6,1,95),"'")) -> 'Quilpolemu 7170' | F21: 13104 | G21: 13 | H21: 29-11-1967 | I21: =CONCATENATE("INSERT INTO CLIENTES(RUT_CLIENTE,RAZON_SOCIAL,DIRECCION,ID_COMUNA,ID_REGION,FECHA_NACIMIENTO) VALUES (",C21,",",D21,",",E21,",",F21,",",G21,",","TO_DATE('",H21,"','DD-MM-YYYY'));") -> INSERT INTO CLIENTES(RUT_CLIENTE,RAZON_SOCIAL,DIRECCION,ID_COMUNA,ID_REGION,FECHA_NACIMIENTO) VALUES (NULL,'Lorena - Quilpolemu 7170','Quilpolemu 7170',13104,13,TO_DATE('29-11-1967','DD-MM-YYYY'));
A22: =Clientes!A7 -> Sandra Arriagada | B22: =B21+1 -> 5 | C22: =IF(ISBLANK(Clientes!L7),"NULL",CONCATENATE("'",Clientes!L7,"'")) -> NULL | D22: =CONCATENATE("'",Clientes!A7,"'") -> 'Sandra Arriagada' | E22: =IF(ISBLANK(Clientes!C7),"'Sin Direccion'",CONCATENATE("'",MID(Clientes!C7,1,95),"'")) -> 'Tacora 9421' | F22: 13105 | G22: 13 | H22: 29-11-1967 | I22: =CONCATENATE("INSERT INTO CLIENTES(RUT_CLIENTE,RAZON_SOCIAL,DIRECCION,ID_COMUNA,ID_REGION,FECHA_NACIMIENTO) VALUES (",C22,",",D22,",",E22,",",F22,",",G22,",","TO_DATE('",H22,"','DD-MM-YYYY'));") -> INSERT INTO CLIENTES(RUT_CLIENTE,RAZON_SOCIAL,DIRECCION,ID_COMUNA,ID_REGION,FECHA_NACIMIENTO) VALUES (NULL,'Sandra Arriagada','Tacora 9421',13105,13,TO_DATE('29-11-1967','DD-MM-YYYY'));
A23: =Clientes!A8 -> Yoli - Palena 2953 | B23: =B22+1 -> 6 | C23: =IF(ISBLANK(Clientes!L8),"NULL",CONCATENATE("'",Clientes!L8,"'")) -> NULL | D23: =CONCATENATE("'",Clientes!A8,"'") -> 'Yoli - Palena 2953' | E23: =IF(ISBLANK(Clientes!C8),"'Sin Direccion'",CONCATENATE("'",MID(Clientes!C8,1,95),"'")) -> 'Palena 2953' | F23: 13106 | G23: 13 | H23: 29-11-1967 | I23: =CONCATENATE("INSERT INTO CLIENTES(RUT_CLIENTE,RAZON_SOCIAL,DIRECCION,ID_COMUNA,ID_REGION,FECHA_NACIMIENTO) VALUES (",C23,",",D23,",",E23,",",F23,",",G23,",","TO_DATE('",H23,"','DD-MM-YYYY'));") -> INSERT INTO CLIENTES(RUT_CLIENTE,RAZON_SOCIAL,DIRECCION,ID_COMUNA,ID_REGION,FECHA_NACIMIENTO) VALUES (NULL,'Yoli - Palena 2953','Palena 2953',13106,13,TO_DATE('29-11-1967','DD-MM-YYYY'));
A24: =Clientes!A9 -> Pamela Medina - Palena 2656 | B24: =B23+1 -> 7 | C24: =IF(ISBLANK(Clientes!L9),"NULL",CONCATENATE("'",Clientes!L9,"'")) -> NULL | D24: =CONCATENATE("'",Clientes!A9,"'") -> 'Pamela Medina - Palena 2656' | E24: =IF(ISBLANK(Clientes!C9),"'Sin Direccion'",CONCATENATE("'",MID(Clientes!C9,1,95),"'")) -> 'Palena 2656' | F24: 13107 | G24: 13 | H24: 29-11-1967 | I24: =CONCATENATE("INSERT INTO CLIENTES(RUT_CLIENTE,RAZON_SOCIAL,DIRECCION,ID_COMUNA,ID_REGION,FECHA_NACIMIENTO) VALUES (",C24,",",D24,",",E24,",",F24,",",G24,",","TO_DATE('",H24,"','DD-MM-YYYY'));") -> INSERT INTO CLIENTES(RUT_CLIENTE,RAZON_SOCIAL,DIRECCION,ID_COMUNA,ID_REGION,FECHA_NACIMIENTO) VALUES (NULL,'Pamela Medina - Palena 2656','Palena 2656',13107,13,TO_DATE('29-11-1967','DD-MM-YYYY'));
A25: =Clientes!A10 -> Pilar Ortiz | B25: =B24+1 -> 8 | C25: =IF(ISBLANK(Clientes!L10),"NULL",CONCATENATE("'",Clientes!L10,"'")) -> NULL | D25: =CONCATENATE("'",Clientes!A10,"'") -> 'Pilar Ortiz' | E25: =IF(ISBLANK(Clientes!C10),"'Sin Direccion'",CONCATENATE("'",MID(Clientes!C10,1,95),"'")) -> 'San agustin 8165' | F25: 13108 | G25: 13 | H25: 29-11-1967 | I25: =CONCATENATE("INSERT INTO CLIENTES(RUT_CLIENTE,RAZON_SOCIAL,DIRECCION,ID_COMUNA,ID_REGION,FECHA_NACIMIENTO) VALUES (",C25,",",D25,",",E25,",",F25,",",G25,",","TO_DATE('",H25,"','DD-MM-YYYY'));") -> INSERT INTO CLIENTES(RUT_CLIENTE,RAZON_SOCIAL,DIRECCION,ID_COMUNA,ID_REGION,FECHA_NACIMIENTO) VALUES (NULL,'Pilar Ortiz','San agustin 8165',13108,13,TO_DATE('29-11-1967','DD-MM-YYYY'));
A26: =Clientes!A11 -> TRAVEL ABROAD EXPERIENCE S.P.A | B26: =B25+1 -> 9 | C26: =IF(ISBLANK(Clientes!L11),"NULL",CONCATENATE("'",Clientes!L11,"'")) -> '77890961-8' | D26: =CONCATENATE("'",Clientes!A11,"'") -> 'TRAVEL ABROAD EXPERIENCE S.P.A' | E26: =IF(ISBLANK(Clientes!C11),"'Sin Direccion'",CONCATENATE("'",MID(Clientes!C11,1,95),"'")) -> 'Avenida Suecia 0155, oficina 304, Providencia' | F26: 13109 | G26: 13 | H26: 29-11-1967 | I26: =CONCATENATE("INSERT INTO CLIENTES(RUT_CLIENTE,RAZON_SOCIAL,DIRECCION,ID_COMUNA,ID_REGION,FECHA_NACIMIENTO) VALUES (",C26,",",D26,",",E26,",",F26,",",G26,",","TO_DATE('",H26,"','DD-MM-YYYY'));") -> INSERT INTO CLIENTES(RUT_CLIENTE,RAZON_SOCIAL,DIRECCION,ID_COMUNA,ID_REGION,FECHA_NACIMIENTO) VALUES ('77890961-8','TRAVEL ABROAD EXPERIENCE S.P.A','Avenida Suecia 0155, oficina 304, Providencia',13109,13,TO_DATE('29-11-1967','DD-MM-YYYY'));
A27: =Clientes!A12 -> Giselle Rojas | B27: =B26+1 -> 10 | C27: =IF(ISBLANK(Clientes!L12),"NULL",CONCATENATE("'",Clientes!L12,"'")) -> NULL | D27: =CONCATENATE("'",Clientes!A12,"'") -> 'Giselle Rojas' | E27: =IF(ISBLANK(Clientes!C12),"'Sin Direccion'",CONCATENATE("'",MID(Clientes!C12,1,95),"'")) -> 'Vicente Huidobro 8268 la florida' | F27: 13110 | G27: 13 | H27: 29-11-1967 | I27: =CONCATENATE("INSERT INTO CLIENTES(RUT_CLIENTE,RAZON_SOCIAL,DIRECCION,ID_COMUNA,ID_REGION,FECHA_NACIMIENTO) VALUES (",C27,",",D27,",",E27,",",F27,",",G27,",","TO_DATE('",H27,"','DD-MM-YYYY'));") -> INSERT INTO CLIENTES(RUT_CLIENTE,RAZON_SOCIAL,DIRECCION,ID_COMUNA,ID_REGION,FECHA_NACIMIENTO) VALUES (NULL,'Giselle Rojas','Vicente Huidobro 8268 la florida',13110,13,TO_DATE('29-11-1967','DD-MM-YYYY'));
A28: =Clientes!A13 -> Soledad Gingko Amarillo 8807 | B28: =B27+1 -> 11 | C28: =IF(ISBLANK(Clientes!L13),"NULL",CONCATENATE("'",Clientes!L13,"'")) -> NULL | D28: =CONCATENATE("'",Clientes!A13,"'") -> 'Soledad Gingko Amarillo 8807 ' | E28: =IF(ISBLANK(Clientes!C13),"'Sin Direccion'",CONCATENATE("'",MID(Clientes!C13,1,95),"'")) -> 'Gingko Amarillo #8807' | F28: 13111 | G28: 13 | H28: 29-11-1967 | I28: =CONCATENATE("INSERT INTO CLIENTES(RUT_CLIENTE,RAZON_SOCIAL,DIRECCION,ID_COMUNA,ID_REGION,FECHA_NACIMIENTO) VALUES (",C28,",",D28,",",E28,",",F28,",",G28,",","TO_DATE('",H28,"','DD-MM-YYYY'));") -> INSERT INTO CLIENTES(RUT_CLIENTE,RAZON_SOCIAL,DIRECCION,ID_COMUNA,ID_REGION,FECHA_NACIMIENTO) VALUES (NULL,'Soledad Gingko Amarillo 8807 ','Gingko Amarillo #8807',13111,13,TO_DATE('29-11-1967','DD-MM-YYYY'));
A29: =Clientes!A14 -> Luisa - Bosque Chileno 2418 | B29: =B28+1 -> 12 | C29: =IF(ISBLANK(Clientes!L14),"NULL",CONCATENATE("'",Clientes!L14,"'")) -> NULL | D29: =CONCATENATE("'",Clientes!A14,"'") -> 'Luisa - Bosque Chileno 2418' | E29: =IF(ISBLANK(Clientes!C14),"'Sin Direccion'",CONCATENATE("'",MID(Clientes!C14,1,95),"'")) -> 'Bosque Chileno 2418' | F29: 13112 | G29: 13 | H29: 29-11-1967 | I29: =CONCATENATE("INSERT INTO CLIENTES(RUT_CLIENTE,RAZON_SOCIAL,DIRECCION,ID_COMUNA,ID_REGION,FECHA_NACIMIENTO) VALUES (",C29,",",D29,",",E29,",",F29,",",G29,",","TO_DATE('",H29,"','DD-MM-YYYY'));") -> INSERT INTO CLIENTES(RUT_CLIENTE,RAZON_SOCIAL,DIRECCION,ID_COMUNA,ID_REGION,FECHA_NACIMIENTO) VALUES (NULL,'Luisa - Bosque Chileno 2418','Bosque Chileno 2418',13112,13,TO_DATE('29-11-1967','DD-MM-YYYY'));
A30: =Clientes!A15 -> Poli Azocar | B30: =B29+1 -> 13 | C30: =IF(ISBLANK(Clientes!L15),"NULL",CONCATENATE("'",Clientes!L15,"'")) -> NULL | D30: =CONCATENATE("'",Clientes!A15,"'") -> 'Poli Azocar' | E30: =IF(ISBLANK(Clientes!C15),"'Sin Direccion'",CONCATENATE("'",MID(Clientes!C15,1,95),"'")) -> 'Portezuelo de colina 0870' | F30: 13113 | G30: 13 | H30: 29-11-1967 | I30: =CONCATENATE("INSERT INTO CLIENTES(RUT_CLIENTE,RAZON_SOCIAL,DIRECCION,ID_COMUNA,ID_REGION,FECHA_NACIMIENTO) VALUES (",C30,",",D30,",",E30,",",F30,",",G30,",","TO_DATE('",H30,"','DD-MM-YYYY'));") -> INSERT INTO CLIENTES(RUT_CLIENTE,RAZON_SOCIAL,DIRECCION,ID_COMUNA,ID_REGION,FECHA_NACIMIENTO) VALUES (NULL,'Poli Azocar','Portezuelo de colina 0870',13113,13,TO_DATE('29-11-1967','DD-MM-YYYY'));
... A505: =Clientes!A490 -> Daca Pastelería | B505: =B504+1 -> 488 | C505: =IF(ISBLANK(Clientes!L490),"NULL",CONCATENATE("'",Clientes!L490,"'")) -> '77588015-5' | D505: =CONCATENATE("'",Clientes!A490,"'") -> 'Daca Pastelería' | E505: =IF(ISBLANK(Clientes!C490),"'Sin Direccion'",CONCATENATE("'",MID(Clientes!C490,1,95),"'")) -> 'Rojas Magallanes 055 frente a la estación' | F505: 13120 | G505: 13 | H505: 29-11-1967 | I505: =CONCATENATE("INSERT INTO CLIENTES(RUT_CLIENTE,RAZON_SOCIAL,DIRECCION,ID_COMUNA,ID_REGION,FECHA_NACIMIENTO) VALUES (",C505,",",D505,",",E505,",",F505,",",G505,",","TO_DATE('",H505,"','DD-MM-YYYY'));") -> INSERT INTO CLIENTES(RUT_CLIENTE,RAZON_SOCIAL,DIRECCION,ID_COMUNA,ID_REGION,FECHA_NACIMIENTO) VALUES ('77588015-5','Daca Pastelería','Rojas Magallanes 055 frente a la estación',13120,13,TO_DATE('29-11-1967','DD-MM-YYYY'));
A506: =Clientes!A491 -> 0 | I506: COMMIT;

Sheet PRODUCTOS
A1: x | B1: Id_Producto | C1: Nombre | D1: Script
A2: =MID(Precios!B2,1,60) -> 2 Bandeja HUEVOS EXTRA 30 Huevos | B2: 1 | C2: =CONCATENATE("'",MID(Precios!B2,1,60),"'") -> '2 Bandeja HUEVOS EXTRA 30 Huevos' | D2: =CONCATENATE("INSERT INTO PRODUCTOS (ID_PRODUCTO,NOMBRE) VALUES (",B2,",",C2,");") -> INSERT INTO PRODUCTOS (ID_PRODUCTO,NOMBRE) VALUES (1,'2 Bandeja HUEVOS EXTRA 30 Huevos');
A3: =MID(Precios!B3,1,60) -> TE CEYLAN PREMIUN 100 bolsas | B3: =B2+1 -> 2 | C3: =CONCATENATE("'",MID(Precios!B3,1,60),"'") -> 'TE CEYLAN PREMIUN 100 bolsas' | D3: =CONCATENATE("INSERT INTO PRODUCTOS (ID_PRODUCTO,NOMBRE) VALUES (",B3,",",C3,");") -> INSERT INTO PRODUCTOS (ID_PRODUCTO,NOMBRE) VALUES (2,'TE CEYLAN PREMIUN 100 bolsas');
A4: =MID(Precios!B4,1,60) -> Natura List Alulosa 90ml | B4: =B3+1 -> 3 | C4: =CONCATENATE("'",MID(Precios!B4,1,60),"'") -> 'Natura List Alulosa 90ml' | D4: =CONCATENATE("INSERT INTO PRODUCTOS (ID_PRODUCTO,NOMBRE) VALUES (",B4,",",C4,");") -> INSERT INTO PRODUCTOS (ID_PRODUCTO,NOMBRE) VALUES (3,'Natura List Alulosa 90ml');
A5: =MID(Precios!B5,1,60) -> Recarga Nescafé 130grs | B5: =B4+1 -> 4 | C5: =CONCATENATE("'",MID(Precios!B5,1,60),"'") -> 'Recarga Nescafé 130grs' | D5: =CONCATENATE("INSERT INTO PRODUCTOS (ID_PRODUCTO,NOMBRE) VALUES (",B5,",",C5,");") -> INSERT INTO PRODUCTOS (ID_PRODUCTO,NOMBRE) VALUES (4,'Recarga Nescafé 130grs');
A6: =MID(Precios!B6,1,60) -> 2 x Film Embalaje 1,7kg (1,4kg Neto/350 Metros aprox.) | B6: =B5+1 -> 5 | C6: =CONCATENATE("'",MID(Precios!B6,1,60),"'") -> '2 x Film Embalaje 1,7kg (1,4kg Neto/350 Metros aprox.)' | D6: =CONCATENATE("INSERT INTO PRODUCTOS (ID_PRODUCTO,NOMBRE) VALUES (",B6,",",C6,");") -> INSERT INTO PRODUCTOS (ID_PRODUCTO,NOMBRE) VALUES (5,'2 x Film Embalaje 1,7kg (1,4kg Neto/350 Metros aprox.)');
A7: =MID(Precios!B7,1,60) -> 2 x Queso Rueda Cabra / 200 gramos) | B7: =B6+1 -> 6 | C7: =CONCATENATE("'",MID(Precios!B7,1,60),"'") -> '2 x Queso Rueda Cabra / 200 gramos)' | D7: =CONCATENATE("INSERT INTO PRODUCTOS (ID_PRODUCTO,NOMBRE) VALUES (",B7,",",C7,");") -> INSERT INTO PRODUCTOS (ID_PRODUCTO,NOMBRE) VALUES (6,'2 x Queso Rueda Cabra / 200 gramos)');
A8: =MID(Precios!B8,1,60) -> 2 x Queso Rueda Sabores / 200 gramos) | B8: =B7+1 -> 7 | C8: =CONCATENATE("'",MID(Precios!B8,1,60),"'") -> '2 x Queso Rueda Sabores / 200 gramos)' | D8: =CONCATENATE("INSERT INTO PRODUCTOS (ID_PRODUCTO,NOMBRE) VALUES (",B8,",",C8,");") -> INSERT INTO PRODUCTOS (ID_PRODUCTO,NOMBRE) VALUES (7,'2 x Queso Rueda Sabores / 200 gramos)');
A9: =MID(Precios!B9,1,60) -> 3 Bandeja HUEVOS EXTRA 30 Huevos | B9: =B8+1 -> 8 | C9: =CONCATENATE("'",MID(Precios!B9,1,60),"'") -> '3 Bandeja HUEVOS EXTRA 30 Huevos' | D9: =CONCATENATE("INSERT INTO PRODUCTOS (ID_PRODUCTO,NOMBRE) VALUES (",B9,",",C9,");") -> INSERT INTO PRODUCTOS (ID_PRODUCTO,NOMBRE) VALUES (8,'3 Bandeja HUEVOS EXTRA 30 Huevos');
A10: =MID(Precios!B10,1,60) -> 3 Toalla Jumbo OVELLA D/H / 100 metros | B10: =B9+1 -> 9 | C10: =CONCATENATE("'",MID(Precios!B10,1,60),"'") -> '3 Toalla Jumbo OVELLA D/H / 100 metros' | D10: =CONCATENATE("INSERT INTO PRODUCTOS (ID_PRODUCTO,NOMBRE) VALUES (",B10,",",C10,");") -> INSERT INTO PRODUCTOS (ID_PRODUCTO,NOMBRE) VALUES (9,'3 Toalla Jumbo OVELLA D/H / 100 metros');
A11: =MID(Precios!B11,1,60) -> Paños Cocina Fibra (30x50 cm) | B11: =B10+1 -> 10 | C11: =CONCATENATE("'",MID(Precios!B11,1,60),"'") -> 'Paños Cocina Fibra (30x50 cm)' | D11: =CONCATENATE("INSERT INTO PRODUCTOS (ID_PRODUCTO,NOMBRE) VALUES (",B11,",",C11,");") -> INSERT INTO PRODUCTOS (ID_PRODUCTO,NOMBRE) VALUES (10,'Paños Cocina Fibra (30x50 cm)');
A12: =MID(Precios!B12,1,60) -> Pack 3 Paños Cocina Fibra (30x50 cm) | B12: =B11+1 -> 11 | C12: =CONCATENATE("'",MID(Precios!B12,1,60),"'") -> 'Pack 3 Paños Cocina Fibra (30x50 cm)' | D12: =CONCATENATE("INSERT INTO PRODUCTOS (ID_PRODUCTO,NOMBRE) VALUES (",B12,",",C12,");") -> INSERT INTO PRODUCTOS (ID_PRODUCTO,NOMBRE) VALUES (11,'Pack 3 Paños Cocina Fibra (30x50 cm)');
A13: =MID(Precios!B13,1,60) -> Guantes Latex Talle M | B13: =B12+1 -> 12 | C13: =CONCATENATE("'",MID(Precios!B13,1,60),"'") -> 'Guantes Latex Talle M' | D13: =CONCATENATE("INSERT INTO PRODUCTOS (ID_PRODUCTO,NOMBRE) VALUES (",B13,",",C13,");") -> INSERT INTO PRODUCTOS (ID_PRODUCTO,NOMBRE) VALUES (12,'Guantes Latex Talle M');
A14: =MID(Precios!B14,1,60) -> Guantes Latex Talle S | B14: =B13+1 -> 13 | C14: =CONCATENATE("'",MID(Precios!B14,1,60),"'") -> 'Guantes Latex Talle S' | D14: =CONCATENATE("INSERT INTO PRODUCTOS (ID_PRODUCTO,NOMBRE) VALUES (",B14,",",C14,");") -> INSERT INTO PRODUCTOS (ID_PRODUCTO,NOMBRE) VALUES (13,'Guantes Latex Talle S');
... A388: =MID(Precios!B388,1,60) -> Wyn 750 cc | B388: =B387+1 -> 387 | C388: =CONCATENATE("'",MID(Precios!B388,1,60),"'") -> 'Wyn 750 cc' | D388: =CONCATENATE("INSERT INTO PRODUCTOS (ID_PRODUCTO,NOMBRE) VALUES (",B388,",",C388,");") -> INSERT INTO PRODUCTOS (ID_PRODUCTO,NOMBRE) VALUES (387,'Wyn 750 cc');
A389: =MID(Precios!B389,1,60) | D389: COMMIT;

Sheet PRECIOS_BD
A1: Fecha_Inicio | B1: Fecha_Fin | C1: Precio | D1: Id_Producto | E1: Script
A2: 01-01-2025 | B2: 31-12-2025 | C2: =ROUND(Precios!M2,0) -> 18639 | D2: 1 | E2: =CONCATENATE("INSERT INTO PRECIOS (FECHA_INICIO, FECHA_FIN,PRECIO,ID_PRODUCTO) VALUES ( TO_DATE(","'",A2,"'",",'DD-MM-YYYY')",", TO_DATE(","'",B2,"'",",'DD-MM-YYYY')",",",C2,",",D2,");") -> INSERT INTO PRECIOS (FECHA_INICIO, FECHA_FIN,PRECIO,ID_PRODUCTO) VALUES ( TO_DATE('01-01-2025','DD-MM-YYYY'), TO_DATE('31-12-2025','DD-MM-YYYY'),18639,1);
A3: 01-01-2025 | B3: 31-12-2025 | C3: =ROUND(Precios!M3,0) -> 5000 | D3: =D2+1 -> 2 | E3: =CONCATENATE("INSERT INTO PRECIOS (FECHA_INICIO, FECHA_FIN,PRECIO,ID_PRODUCTO) VALUES ( TO_DATE(","'",A3,"'",",'DD-MM-YYYY')",", TO_DATE(","'",B3,"'",",'DD-MM-YYYY')",",",C3,",",D3,");") -> INSERT INTO PRECIOS (FECHA_INICIO, FECHA_FIN,PRECIO,ID_PRODUCTO) VALUES ( TO_DATE('01-01-2025','DD-MM-YYYY'), TO_DATE('31-12-2025','DD-MM-YYYY'),5000,2);
A4: 01-01-2025 | B4: 31-12-2025 | C4: =ROUND(Precios!M4,0) -> 2300 | D4: =D3+1 -> 3 | E4: =CONCATENATE("INSERT INTO PRECIOS (FECHA_INICIO, FECHA_FIN,PRECIO,ID_PRODUCTO) VALUES ( TO_DATE(","'",A4,"'",",'DD-MM-YYYY')",", TO_DATE(","'",B4,"'",",'DD-MM-YYYY')",",",C4,",",D4,");") -> INSERT INTO PRECIOS (FECHA_INICIO, FECHA_FIN,PRECIO,ID_PRODUCTO) VALUES ( TO_DATE('01-01-2025','DD-MM-YYYY'), TO_DATE('31-12-2025','DD-MM-YYYY'),2300,3);
A5: 01-01-2025 | B5: 31-12-2025 | C5: =ROUND(Precios!M5,0) -> 5000 | D5: =D4+1 -> 4 | E5: =CONCATENATE("INSERT INTO PRECIOS (FECHA_INICIO, FECHA_FIN,PRECIO,ID_PRODUCTO) VALUES ( TO_DATE(","'",A5,"'",",'DD-MM-YYYY')",", TO_DATE(","'",B5,"'",",'DD-MM-YYYY')",",",C5,",",D5,");") -> INSERT INTO PRECIOS (FECHA_INICIO, FECHA_FIN,PRECIO,ID_PRODUCTO) VALUES ( TO_DATE('01-01-2025','DD-MM-YYYY'), TO_DATE('31-12-2025','DD-MM-YYYY'),5000,4);
A6: 01-01-2025 | B6: 31-12-2025 | C6: =ROUND(Precios!M6,0) -> 11000 | D6: =D5+1 -> 5 | E6: =CONCATENATE("INSERT INTO PRECIOS (FECHA_INICIO, FECHA_FIN,PRECIO,ID_PRODUCTO) VALUES ( TO_DATE(","'",A6,"'",",'DD-MM-YYYY')",", TO_DATE(","'",B6,"'",",'DD-MM-YYYY')",",",C6,",",D6,");") -> INSERT INTO PRECIOS (FECHA_INICIO, FECHA_FIN,PRECIO,ID_PRODUCTO) VALUES ( TO_DATE('01-01-2025','DD-MM-YYYY'), TO_DATE('31-12-2025','DD-MM-YYYY'),11000,5);
A7: 01-01-2025 | B7: 31-12-2025 | C7: =ROUND(Precios!M7,0) -> 9400 | D7: =D6+1 -> 6 | E7: =CONCATENATE("INSERT INTO PRECIOS (FECHA_INICIO, FECHA_FIN,PRECIO,ID_PRODUCTO) VALUES ( TO_DATE(","'",A7,"'",",'DD-MM-YYYY')",", TO_DATE(","'",B7,"'",",'DD-MM-YYYY')",",",C7,",",D7,");") -> INSERT INTO PRECIOS (FECHA_INICIO, FECHA_FIN,PRECIO,ID_PRODUCTO) VALUES ( TO_DATE('01-01-2025','DD-MM-YYYY'), TO_DATE('31-12-2025','DD-MM-YYYY'),9400,6);
A8: 01-01-2025 | B8: 31-12-2025 | C8: =ROUND(Precios!M8,0) -> 7000 | D8: =D7+1 -> 7 | E8: =CONCATENATE("INSERT INTO PRECIOS (FECHA_INICIO, FECHA_FIN,PRECIO,ID_PRODUCTO) VALUES ( TO_DATE(","'",A8,"'",",'DD-MM-YYYY')",", TO_DATE(","'",B8,"'",",'DD-MM-YYYY')",",",C8,",",D8,");") -> INSERT INTO PRECIOS (FECHA_INICIO, FECHA_FIN,PRECIO,ID_PRODUCTO) VALUES ( TO_DATE('01-01-2025','DD-MM-YYYY'), TO_DATE('31-12-2025','DD-MM-YYYY'),7000,7);
A9: 01-01-2025 | B9: 31-12-2025 | C9: =ROUND(Precios!M9,0) -> 27620 | D9: =D8+1 -> 8 | E9: =CONCATENATE("INSERT INTO PRECIOS (FECHA_INICIO, FECHA_FIN,PRECIO,ID_PRODUCTO) VALUES ( TO_DATE(","'",A9,"'",",'DD-MM-YYYY')",", TO_DATE(","'",B9,"'",",'DD-MM-YYYY')",",",C9,",",D9,");") -> INSERT INTO PRECIOS (FECHA_INICIO, FECHA_FIN,PRECIO,ID_PRODUCTO) VALUES ( TO_DATE('01-01-2025','DD-MM-YYYY'), TO_DATE('31-12-2025','DD-MM-YYYY'),27620,8);
A10: 01-01-2025 | B10: 31-12-2025 | C10: =ROUND(Precios!M10,0) -> 10900 | D10: =D9+1 -> 9 | E10: =CONCATENATE("INSERT INTO PRECIOS (FECHA_INICIO, FECHA_FIN,PRECIO,ID_PRODUCTO) VALUES ( TO_DATE(","'",A10,"'",",'DD-MM-YYYY')",", TO_DATE(","'",B10,"'",",'DD-MM-YYYY')",",",C10,",",D10,");") -> INSERT INTO PRECIOS (FECHA_INICIO, FECHA_FIN,PRECIO,ID_PRODUCTO) VALUES ( TO_DATE('01-01-2025','DD-MM-YYYY'), TO_DATE('31-12-2025','DD-MM-YYYY'),10900,9);
A11: 01-01-2025 | B11: 31-12-2025 | C11: =ROUND(Precios!M11,0) -> 1000 | D11: =D10+1 -> 10 | E11: =CONCATENATE("INSERT INTO PRECIOS (FECHA_INICIO, FECHA_FIN,PRECIO,ID_PRODUCTO) VALUES ( TO_DATE(","'",A11,"'",",'DD-MM-YYYY')",", TO_DATE(","'",B11,"'",",'DD-MM-YYYY')",",",C11,",",D11,");") -> INSERT INTO PRECIOS (FECHA_INICIO, FECHA_FIN,PRECIO,ID_PRODUCTO) VALUES ( TO_DATE('01-01-2025','DD-MM-YYYY'), TO_DATE('31-12-2025','DD-MM-YYYY'),1000,10);
A12: 01-01-2025 | B12: 31-12-2025 | C12: =ROUND(Precios!M12,0) -> 2500 | D12: =D11+1 -> 11 | E12: =CONCATENATE("INSERT INTO PRECIOS (FECHA_INICIO, FECHA_FIN,PRECIO,ID_PRODUCTO) VALUES ( TO_DATE(","'",A12,"'",",'DD-MM-YYYY')",", TO_DATE(","'",B12,"'",",'DD-MM-YYYY')",",",C12,",",D12,");") -> INSERT INTO PRECIOS (FECHA_INICIO, FECHA_FIN,PRECIO,ID_PRODUCTO) VALUES ( TO_DATE('01-01-2025','DD-MM-YYYY'), TO_DATE('31-12-2025','DD-MM-YYYY'),2500,11);
A13: 01-01-2025 | B13: 31-12-2025 | C13: =ROUND(Precios!M13,0) -> 700 | D13: =D12+1 -> 12 | E13: =CONCATENATE("INSERT INTO PRECIOS (FECHA_INICIO, FECHA_FIN,PRECIO,ID_PRODUCTO) VALUES ( TO_DATE(","'",A13,"'",",'DD-MM-YYYY')",", TO_DATE(","'",B13,"'",",'DD-MM-YYYY')",",",C13,",",D13,");") -> INSERT INTO PRECIOS (FECHA_INICIO, FECHA_FIN,PRECIO,ID_PRODUCTO) VALUES ( TO_DATE('01-01-2025','DD-MM-YYYY'), TO_DATE('31-12-2025','DD-MM-YYYY'),700,12);
A14: 01-01-2025 | B14: 31-12-2025 | C14: =ROUND(Precios!M14,0) -> 700 | D14: =D13+1 -> 13 | E14: =CONCATENATE("INSERT INTO PRECIOS (FECHA_INICIO, FECHA_FIN,PRECIO,ID_PRODUCTO) VALUES ( TO_DATE(","'",A14,"'",",'DD-MM-YYYY')",", TO_DATE(","'",B14,"'",",'DD-MM-YYYY')",",",C14,",",D14,");") -> INSERT INTO PRECIOS (FECHA_INICIO, FECHA_FIN,PRECIO,ID_PRODUCTO) VALUES ( TO_DATE('01-01-2025','DD-MM-YYYY'), TO_DATE('31-12-2025','DD-MM-YYYY'),700,13);
... A388: 01-01-2025 | B388: 31-12-2025 | C388: =ROUND(Precios!M388,0) -> 1500 | D388: =D387+1 -> 387 | E388: =CONCATENATE("INSERT INTO PRECIOS (FECHA_INICIO, FECHA_FIN,PRECIO,ID_PRODUCTO) VALUES ( TO_DATE(","'",A388,"'",",'DD-MM-YYYY')",", TO_DATE(","'",B388,"'",",'DD-MM-YYYY')",",",C388,",",D388,");") -> INSERT INTO PRECIOS (FECHA_INICIO, FECHA_FIN,PRECIO,ID_PRODUCTO) VALUES ( TO_DATE('01-01-2025','DD-MM-YYYY'), TO_DATE('31-12-2025','DD-MM-YYYY'),1500,387);
E389: COMMIT;

Sheet DOCUMENTOS
F3: Valores
A4: Id_Tipo | B4: Nro_Documento | C4: Fecha_Emision | D4: Rut_Empleado | E4: Id_Cliente | F4: Total Bruto | G4: Total Neto | H4: Total Iva | I4: Id_Tipo | J4: Script
A5: 1 | B5: 1 | C5: 02-01-2025 | D5: 14526149-K | E5: 108 | F5: 10600 | G5: 8908 | H5: 1692 | I5: 1 | J5: =CONCATENATE("INSERT INTO DOCUMENTOS (NRO_DOCUMENTO,FECHA_EMISION,TOTAL_BRUTO,TOTAL_NETO,TOTAL_IVA, ID_TIPO, RUT_EMPLEADO, ID_CLIENTE) VALUES(",B5,",","TO_DATE('",C5,"'",",'DD-MM-YYYY'),",F5,",",G5,",",H5,",",I5,",","'",D5,"',",E5,");") -> INSERT INTO DOCUMENTOS (NRO_DOCUMENTO,FECHA_EMISION,TOTAL_BRUTO,TOTAL_NETO,TOTAL_IVA, ID_TIPO, RUT_EMPLEADO, ID_CLIENTE) VALUES(1,TO_DATE('02-01-2025','DD-MM-YYYY'),10600,8908,1692,1,'14526149-K',108);
B6: 2 | C6: 02-01-2025 | D6: 14526149-K | E6: 110 | F6: 14000 | G6: 11765 | H6: 2235 | I6: 1 | J6: =CONCATENATE("INSERT INTO DOCUMENTOS (NRO_DOCUMENTO,FECHA_EMISION,TOTAL_BRUTO,TOTAL_NETO,TOTAL_IVA, ID_TIPO, RUT_EMPLEADO, ID_CLIENTE) VALUES(",B6,",","TO_DATE('",C6,"'",",'DD-MM-YYYY'),",F6,",",G6,",",H6,",",I6,",","'",D6,"',",E6,");") -> INSERT INTO DOCUMENTOS (NRO_DOCUMENTO,FECHA_EMISION,TOTAL_BRUTO,TOTAL_NETO,TOTAL_IVA, ID_TIPO, RUT_EMPLEADO, ID_CLIENTE) VALUES(2,TO_DATE('02-01-2025','DD-MM-YYYY'),14000,11765,2235,1,'14526149-K',110);
B7: 3 | C7: 02-01-2025 | D7: 14526149-K | E7: 111 | F7: 15500 | G7: 13025 | H7: 2475 | I7: 1 | J7: =CONCATENATE("INSERT INTO DOCUMENTOS (NRO_DOCUMENTO,FECHA_EMISION,TOTAL_BRUTO,TOTAL_NETO,TOTAL_IVA, ID_TIPO, RUT_EMPLEADO, ID_CLIENTE) VALUES(",B7,",","TO_DATE('",C7,"'",",'DD-MM-YYYY'),",F7,",",G7,",",H7,",",I7,",","'",D7,"',",E7,");") -> INSERT INTO DOCUMENTOS (NRO_DOCUMENTO,FECHA_EMISION,TOTAL_BRUTO,TOTAL_NETO,TOTAL_IVA, ID_TIPO, RUT_EMPLEADO, ID_CLIENTE) VALUES(3,TO_DATE('02-01-2025','DD-MM-YYYY'),15500,13025,2475,1,'14526149-K',111);
B8: 4 | C8: 02-01-2025 | D8: 14526149-K | E8: 116 | F8: 20900 | G8: 17562 | H8: 3338 | I8: 1 | J8: =CONCATENATE("INSERT INTO DOCUMENTOS (NRO_DOCUMENTO,FECHA_EMISION,TOTAL_BRUTO,TOTAL_NETO,TOTAL_IVA, ID_TIPO, RUT_EMPLEADO, ID_CLIENTE) VALUES(",B8,",","TO_DATE('",C8,"'",",'DD-MM-YYYY'),",F8,",",G8,",",H8,",",I8,",","'",D8,"',",E8,");") -> INSERT INTO DOCUMENTOS (NRO_DOCUMENTO,FECHA_EMISION,TOTAL_BRUTO,TOTAL_NETO,TOTAL_IVA, ID_TIPO, RUT_EMPLEADO, ID_CLIENTE) VALUES(4,TO_DATE('02-01-2025','DD-MM-YYYY'),20900,17562,3338,1,'14526149-K',116);
B9: 5 | C9: 02-01-2025 | D9: 14526149-K | E9: 119 | F9: 12000 | G9: 10084 | H9: 1916 | I9: 1 | J9: =CONCATENATE("INSERT INTO DOCUMENTOS (NRO_DOCUMENTO,FECHA_EMISION,TOTAL_BRUTO,TOTAL_NETO,TOTAL_IVA, ID_TIPO, RUT_EMPLEADO, ID_CLIENTE) VALUES(",B9,",","TO_DATE('",C9,"'",",'DD-MM-YYYY'),",F9,",",G9,",",H9,",",I9,",","'",D9,"',",E9,");") -> INSERT INTO DOCUMENTOS (NRO_DOCUMENTO,FECHA_EMISION,TOTAL_BRUTO,TOTAL_NETO,TOTAL_IVA, ID_TIPO, RUT_EMPLEADO, ID_CLIENTE) VALUES(5,TO_DATE('02-01-2025','DD-MM-YYYY'),12000,10084,1916,1,'14526149-K',119);
B10: 6 | C10: 02-01-2025 | D10: 14526149-K | E10: 166 | F10: 7250 | G10: 6092 | H10: 1158 | I10: 1 | J10: =CONCATENATE("INSERT INTO DOCUMENTOS (NRO_DOCUMENTO,FECHA_EMISION,TOTAL_BRUTO,TOTAL_NETO,TOTAL_IVA, ID_TIPO, RUT_EMPLEADO, ID_CLIENTE) VALUES(",B10,",","TO_DATE('",C10,"'",",'DD-MM-YYYY'),",F10,",",G10,",",H10,",",I10,",","'",D10,"',",E10,");") -> INSERT INTO DOCUMENTOS (NRO_DOCUMENTO,FECHA_EMISION,TOTAL_BRUTO,TOTAL_NETO,TOTAL_IVA, ID_TIPO, RUT_EMPLEADO, ID_CLIENTE) VALUES(6,TO_DATE('02-01-2025','DD-MM-YYYY'),7250,6092,1158,1,'14526149-K',166);
B11: 7 | C11: 02-01-2025 | D11: 14526149-K | E11: 219 | F11: 26490 | G11: 22260 | H11: 4230 | I11: 1 | J11: =CONCATENATE("INSERT INTO DOCUMENTOS (NRO_DOCUMENTO,FECHA_EMISION,TOTAL_BRUTO,TOTAL_NETO,TOTAL_IVA, ID_TIPO, RUT_EMPLEADO, ID_CLIENTE) VALUES(",B11,",","TO_DATE('",C11,"'",",'DD-MM-YYYY'),",F11,",",G11,",",H11,",",I11,",","'",D11,"',",E11,");") -> INSERT INTO DOCUMENTOS (NRO_DOCUMENTO,FECHA_EMISION,TOTAL_BRUTO,TOTAL_NETO,TOTAL_IVA, ID_TIPO, RUT_EMPLEADO, ID_CLIENTE) VALUES(7,TO_DATE('02-01-2025','DD-MM-YYYY'),26490,22260,4230,1,'14526149-K',219);
B12: 8 | C12: 02-01-2025 | D12: 14526149-K | E12: 353 | F12: 19990 | G12: 16798 | H12: 3192 | I12: 1 | J12: =CONCATENATE("INSERT INTO DOCUMENTOS (NRO_DOCUMENTO,FECHA_EMISION,TOTAL_BRUTO,TOTAL_NETO,TOTAL_IVA, ID_TIPO, RUT_EMPLEADO, ID_CLIENTE) VALUES(",B12,",","TO_DATE('",C12,"'",",'DD-MM-YYYY'),",F12,",",G12,",",H12,",",I12,",","'",D12,"',",E12,");") -> INSERT INTO DOCUMENTOS (NRO_DOCUMENTO,FECHA_EMISION,TOTAL_BRUTO,TOTAL_NETO,TOTAL_IVA, ID_TIPO, RUT_EMPLEADO, ID_CLIENTE) VALUES(8,TO_DATE('02-01-2025','DD-MM-YYYY'),19990,16798,3192,1,'14526149-K',353);
B13: 9 | C13: 02-01-2025 | D13: 14526149-K | E13: 374 | F13: 10500 | G13: 8824 | H13: 1676 | I13: 1 | J13: =CONCATENATE("INSERT INTO DOCUMENTOS (NRO_DOCUMENTO,FECHA_EMISION,TOTAL_BRUTO,TOTAL_NETO,TOTAL_IVA, ID_TIPO, RUT_EMPLEADO, ID_CLIENTE) VALUES(",B13,",","TO_DATE('",C13,"'",",'DD-MM-YYYY'),",F13,",",G13,",",H13,",",I13,",","'",D13,"',",E13,");") -> INSERT INTO DOCUMENTOS (NRO_DOCUMENTO,FECHA_EMISION,TOTAL_BRUTO,TOTAL_NETO,TOTAL_IVA, ID_TIPO, RUT_EMPLEADO, ID_CLIENTE) VALUES(9,TO_DATE('02-01-2025','DD-MM-YYYY'),10500,8824,1676,1,'14526149-K',374);
B14: 10 | C14: 02-01-2025 | D14: 14526149-K | E14: 446 | F14: 11500 | G14: 9664 | H14: 1836 | I14: 1 | J14: =CONCATENATE("INSERT INTO DOCUMENTOS (NRO_DOCUMENTO,FECHA_EMISION,TOTAL_BRUTO,TOTAL_NETO,TOTAL_IVA, ID_TIPO, RUT_EMPLEADO, ID_CLIENTE) VALUES(",B14,",","TO_DATE('",C14,"'",",'DD-MM-YYYY'),",F14,",",G14,",",H14,",",I14,",","'",D14,"',",E14,");") -> INSERT INTO DOCUMENTOS (NRO_DOCUMENTO,FECHA_EMISION,TOTAL_BRUTO,TOTAL_NETO,TOTAL_IVA, ID_TIPO, RUT_EMPLEADO, ID_CLIENTE) VALUES(10,TO_DATE('02-01-2025','DD-MM-YYYY'),11500,9664,1836,1,'14526149-K',446);
B15: 11 | C15: 02-01-2025 | D15: 14526149-K | E15: 457 | F15: 15500 | G15: 13025 | H15: 2475 | I15: 1 | J15: =CONCATENATE("INSERT INTO DOCUMENTOS (NRO_DOCUMENTO,FECHA_EMISION,TOTAL_BRUTO,TOTAL_NETO,TOTAL_IVA, ID_TIPO, RUT_EMPLEADO, ID_CLIENTE) VALUES(",B15,",","TO_DATE('",C15,"'",",'DD-MM-YYYY'),",F15,",",G15,",",H15,",",I15,",","'",D15,"',",E15,");") -> INSERT INTO DOCUMENTOS (NRO_DOCUMENTO,FECHA_EMISION,TOTAL_BRUTO,TOTAL_NETO,TOTAL_IVA, ID_TIPO, RUT_EMPLEADO, ID_CLIENTE) VALUES(11,TO_DATE('02-01-2025','DD-MM-YYYY'),15500,13025,2475,1,'14526149-K',457);
B16: 12 | C16: 02-01-2025 | D16: 14526149-K | E16: 469 | F16: 6500 | G16: 5462 | H16: 1038 | I16: 1 | J16: =CONCATENATE("INSERT INTO DOCUMENTOS (NRO_DOCUMENTO,FECHA_EMISION,TOTAL_BRUTO,TOTAL_NETO,TOTAL_IVA, ID_TIPO, RUT_EMPLEADO, ID_CLIENTE) VALUES(",B16,",","TO_DATE('",C16,"'",",'DD-MM-YYYY'),",F16,",",G16,",",H16,",",I16,",","'",D16,"',",E16,");") -> INSERT INTO DOCUMENTOS (NRO_DOCUMENTO,FECHA_EMISION,TOTAL_BRUTO,TOTAL_NETO,TOTAL_IVA, ID_TIPO, RUT_EMPLEADO, ID_CLIENTE) VALUES(12,TO_DATE('02-01-2025','DD-MM-YYYY'),6500,5462,1038,1,'14526149-K',469);
B17: 13 | C17: 02-01-2025 | D17: 14526149-K | E17: 470 | F17: 6900 | G17: 5798 | H17: 1102 | I17: 1 | J17: =CONCATENATE("INSERT INTO DOCUMENTOS (NRO_DOCUMENTO,FECHA_EMISION,TOTAL_BRUTO,TOTAL_NETO,TOTAL_IVA, ID_TIPO, RUT_EMPLEADO, ID_CLIENTE) VALUES(",B17,",","TO_DATE('",C17,"'",",'DD-MM-YYYY'),",F17,",",G17,",",H17,",",I17,",","'",D17,"',",E17,");") -> INSERT INTO DOCUMENTOS (NRO_DOCUMENTO,FECHA_EMISION,TOTAL_BRUTO,TOTAL_NETO,TOTAL_IVA, ID_TIPO, RUT_EMPLEADO, ID_CLIENTE) VALUES(13,TO_DATE('02-01-2025','DD-MM-YYYY'),6900,5798,1102,1,'14526149-K',470);
... B1559: 1555 | C1559: 18-09-2025 | D1559: 14526149-K | E1559: 166 | F1559: 11000 | G1559: 9244 | H1559: 1756 | I1559: 1 | J1559: =CONCATENATE("INSERT INTO DOCUMENTOS (NRO_DOCUMENTO,FECHA_EMISION,TOTAL_BRUTO,TOTAL_NETO,TOTAL_IVA, ID_TIPO, RUT_EMPLEADO, ID_CLIENTE) VALUES(",B1559,",","TO_DATE('",C1559,"'",",'DD-MM-YYYY'),",F1559,",",G1559,",",H1559,",",I1559,",","'",D1559,"',",E1559,");") -> INSERT INTO DOCUMENTOS (NRO_DOCUMENTO,FECHA_EMISION,TOTAL_BRUTO,TOTAL_NETO,TOTAL_IVA, ID_TIPO, RUT_EMPLEADO, ID_CLIENTE) VALUES(1555,TO_DATE('18-09-2025','DD-MM-YYYY'),11000,9244,1756,1,'14526149-K',166);
A1560: 2 | B1560: 1 | C1560: 04-01-2025 | D1560: 14526149-K | E1560: 413 | F1560: 116990 | G1560: 98311 | H1560: 18679 | I1560: 2 | J1560: =CONCATENATE("INSERT INTO DOCUMENTOS (NRO_DOCUMENTO,FECHA_EMISION,TOTAL_BRUTO,TOTAL_NETO,TOTAL_IVA, ID_TIPO, RUT_EMPLEADO, ID_CLIENTE) VALUES(",B1560,",","TO_DATE('",C1560,"'",",'DD-MM-YYYY'),",F1560,",",G1560,",",H1560,",",I1560,",","'",D1560,"',",E1560,");") -> INSERT INTO DOCUMENTOS (NRO_DOCUMENTO,FECHA_EMISION,TOTAL_BRUTO,TOTAL_NETO,TOTAL_IVA, ID_TIPO, RUT_EMPLEADO, ID_CLIENTE) VALUES(1,TO_DATE('04-01-2025','DD-MM-YYYY'),116990,98311,18679,2,'14526149-K',413);
B1561: 2 | C1561: 06-01-2025 | D1561: 14526149-K | E1561: 185 | F1561: 117100 | G1561: 98404 | H1561: 18696 | I1561: 2 | J1561: =CONCATENATE("INSERT INTO DOCUMENTOS (NRO_DOCUMENTO,FECHA_EMISION,TOTAL_BRUTO,TOTAL_NETO,TOTAL_IVA, ID_TIPO, RUT_EMPLEADO, ID_CLIENTE) VALUES(",B1561,",","TO_DATE('",C1561,"'",",'DD-MM-YYYY'),",F1561,",",G1561,",",H1561,",",I1561,",","'",D1561,"',",E1561,");") -> INSERT INTO DOCUMENTOS (NRO_DOCUMENTO,FECHA_EMISION,TOTAL_BRUTO,TOTAL_NETO,TOTAL_IVA, ID_TIPO, RUT_EMPLEADO, ID_CLIENTE) VALUES(2,TO_DATE('06-01-2025','DD-MM-YYYY'),117100,98404,18696,2,'14526149-K',185);
B1562: 3 | C1562: 08-01-2025 | D1562: 14526149-K | E1562: 125 | F1562: 63852 | G1562: 53658 | H1562: 10194 | I1562: 2 | J1562: =CONCATENATE("INSERT INTO DOCUMENTOS (NRO_DOCUMENTO,FECHA_EMISION,TOTAL_BRUTO,TOTAL_NETO,TOTAL_IVA, ID_TIPO, RUT_EMPLEADO, ID_CLIENTE) VALUES(",B1562,",","TO_DATE('",C1562,"'",",'DD-MM-YYYY'),",F1562,",",G1562,",",H1562,",",I1562,",","'",D1562,"',",E1562,");") -> INSERT INTO DOCUMENTOS (NRO_DOCUMENTO,FECHA_EMISION,TOTAL_BRUTO,TOTAL_NETO,TOTAL_IVA, ID_TIPO, RUT_EMPLEADO, ID_CLIENTE) VALUES(3,TO_DATE('08-01-2025','DD-MM-YYYY'),63852,53658,10194,2,'14526149-K',125);
B1563: 4 | C1563: 11-01-2025 | D1563: 14526149-K | E1563: 203 | F1563: 6000 | G1563: 5042 | H1563: 958 | I1563: 2 | J1563: =CONCATENATE("INSERT INTO DOCUMENTOS (NRO_DOCUMENTO,FECHA_EMISION,TOTAL_BRUTO,TOTAL_NETO,TOTAL_IVA, ID_TIPO, RUT_EMPLEADO, ID_CLIENTE) VALUES(",B1563,",","TO_DATE('",C1563,"'",",'DD-MM-YYYY'),",F1563,",",G1563,",",H1563,",",I1563,",","'",D1563,"',",E1563,");") -> INSERT INTO DOCUMENTOS (NRO_DOCUMENTO,FECHA_EMISION,TOTAL_BRUTO,TOTAL_NETO,TOTAL_IVA, ID_TIPO, RUT_EMPLEADO, ID_CLIENTE) VALUES(4,TO_DATE('11-01-2025','DD-MM-YYYY'),6000,5042,958,2,'14526149-K',203);
B1564: 5 | C1564: 15-01-2025 | D1564: 14526149-K | E1564: 203 | F1564: 38990 | G1564: 32764 | H1564: 6226 | I1564: 2 | J1564: =CONCATENATE("INSERT INTO DOCUMENTOS (NRO_DOCUMENTO,FECHA_EMISION,TOTAL_BRUTO,TOTAL_NETO,TOTAL_IVA, ID_TIPO, RUT_EMPLEADO, ID_CLIENTE) VALUES(",B1564,",","TO_DATE('",C1564,"'",",'DD-MM-YYYY'),",F1564,",",G1564,",",H1564,",",I1564,",","'",D1564,"',",E1564,");") -> INSERT INTO DOCUMENTOS (NRO_DOCUMENTO,FECHA_EMISION,TOTAL_BRUTO,TOTAL_NETO,TOTAL_IVA, ID_TIPO, RUT_EMPLEADO, ID_CLIENTE) VALUES(5,TO_DATE('15-01-2025','DD-MM-YYYY'),38990,32764,6226,2,'14526149-K',203);
B1565: 6 | C1565: 20-01-2025 | D1565: 14526149-K | E1565: 413 | F1565: 126490 | G1565: 106294 | H1565: 20196 | I1565: 2 | J1565: =CONCATENATE("INSERT INTO DOCUMENTOS (NRO_DOCUMENTO,FECHA_EMISION,TOTAL_BRUTO,TOTAL_NETO,TOTAL_IVA, ID_TIPO, RUT_EMPLEADO, ID_CLIENTE) VALUES(",B1565,",","TO_DATE('",C1565,"'",",'DD-MM-YYYY'),",F1565,",",G1565,",",H1565,",",I1565,",","'",D1565,"',",E1565,");") -> INSERT INTO DOCUMENTOS (NRO_DOCUMENTO,FECHA_EMISION,TOTAL_BRUTO,TOTAL_NETO,TOTAL_IVA, ID_TIPO, RUT_EMPLEADO, ID_CLIENTE) VALUES(6,TO_DATE('20-01-2025','DD-MM-YYYY'),126490,106294,20196,2,'14526149-K',413);
B1566: 7 | C1566: 23-01-2025 | D1566: 14526149-K | E1566: 203 | F1566: 3500 | G1566: 2941 | H1566: 559 | I1566: 2 | J1566: =CONCATENATE("INSERT INTO DOCUMENTOS (NRO_DOCUMENTO,FECHA_EMISION,TOTAL_BRUTO,TOTAL_NETO,TOTAL_IVA, ID_TIPO, RUT_EMPLEADO, ID_CLIENTE) VALUES(",B1566,",","TO_DATE('",C1566,"'",",'DD-MM-YYYY'),",F1566,",",G1566,",",H1566,",",I1566,",","'",D1566,"',",E1566,");") -> INSERT INTO DOCUMENTOS (NRO_DOCUMENTO,FECHA_EMISION,TOTAL_BRUTO,TOTAL_NETO,TOTAL_IVA, ID_TIPO, RUT_EMPLEADO, ID_CLIENTE) VALUES(7,TO_DATE('23-01-2025','DD-MM-YYYY'),3500,2941,559,2,'14526149-K',203);
B1567: 8 | C1567: 07-02-2025 | D1567: 14526149-K | E1567: 203 | F1567: 31300 | G1567: 26302 | H1567: 4998 | I1567: 2 | J1567: =CONCATENATE("INSERT INTO DOCUMENTOS (NRO_DOCUMENTO,FECHA_EMISION,TOTAL_BRUTO,TOTAL_NETO,TOTAL_IVA, ID_TIPO, RUT_EMPLEADO, ID_CLIENTE) VALUES(",B1567,",","TO_DATE('",C1567,"'",",'DD-MM-YYYY'),",F1567,",",G1567,",",H1567,",",I1567,",","'",D1567,"',",E1567,");") -> INSERT INTO DOCUMENTOS (NRO_DOCUMENTO,FECHA_EMISION,TOTAL_BRUTO,TOTAL_NETO,TOTAL_IVA, ID_TIPO, RUT_EMPLEADO, ID_CLIENTE) VALUES(8,TO_DATE('07-02-2025','DD-MM-YYYY'),31300,26302,4998,2,'14526149-K',203);
B1568: 9 | C1568: 09-02-2025 | D1568: 14526149-K | E1568: 125 | F1568: 245200 | G1568: 206051 | H1568: 39149 | I1568: 2 | J1568: =CONCATENATE("INSERT INTO DOCUMENTOS (NRO_DOCUMENTO,FECHA_EMISION,TOTAL_BRUTO,TOTAL_NETO,TOTAL_IVA, ID_TIPO, RUT_EMPLEADO, ID_CLIENTE) VALUES(",B1568,",","TO_DATE('",C1568,"'",",'DD-MM-YYYY'),",F1568,",",G1568,",",H1568,",",I1568,",","'",D1568,"',",E1568,");") -> INSERT INTO DOCUMENTOS (NRO_DOCUMENTO,FECHA_EMISION,TOTAL_BRUTO,TOTAL_NETO,TOTAL_IVA, ID_TIPO, RUT_EMPLEADO, ID_CLIENTE) VALUES(9,TO_DATE('09-02-2025','DD-MM-YYYY'),245200,206051,39149,2,'14526149-K',125);
B1569: 10 | C1569: 12-02-2025 | D1569: 14526149-K | E1569: 180 | F1569: 4400 | G1569: 3697 | H1569: 703 | I1569: 2 | J1569: =CONCATENATE("INSERT INTO DOCUMENTOS (NRO_DOCUMENTO,FECHA_EMISION,TOTAL_BRUTO,TOTAL_NETO,TOTAL_IVA, ID_TIPO, RUT_EMPLEADO, ID_CLIENTE) VALUES(",B1569,",","TO_DATE('",C1569,"'",",'DD-MM-YYYY'),",F1569,",",G1569,",",H1569,",",I1569,",","'",D1569,"',",E1569,");") -> INSERT INTO DOCUMENTOS (NRO_DOCUMENTO,FECHA_EMISION,TOTAL_BRUTO,TOTAL_NETO,TOTAL_IVA, ID_TIPO, RUT_EMPLEADO, ID_CLIENTE) VALUES(10,TO_DATE('12-02-2025','DD-MM-YYYY'),4400,3697,703,2,'14526149-K',180);
B1570: 11 | C1570: 12-02-2025 | D1570: 14526149-K | E1570: 413 | F1570: 91990 | G1570: 77303 | H1570: 14687 | I1570: 2 | J1570: =CONCATENATE("INSERT INTO DOCUMENTOS (NRO_DOCUMENTO,FECHA_EMISION,TOTAL_BRUTO,TOTAL_NETO,TOTAL_IVA, ID_TIPO, RUT_EMPLEADO, ID_CLIENTE) VALUES(",B1570,",","TO_DATE('",C1570,"'",",'DD-MM-YYYY'),",F1570,",",G1570,",",H1570,",",I1570,",","'",D1570,"',",E1570,");") -> INSERT INTO DOCUMENTOS (NRO_DOCUMENTO,FECHA_EMISION,TOTAL_BRUTO,TOTAL_NETO,TOTAL_IVA, ID_TIPO, RUT_EMPLEADO, ID_CLIENTE) VALUES(11,TO_DATE('12-02-2025','DD-MM-YYYY'),91990,77303,14687,2,'14526149-K',413);
B1571: 12 | C1571: 14-02-2025 | D1571: 14526149-K | E1571: 203 | F1571: 51490 | G1571: 43268 | H1571: 8222 | I1571: 2 | J1571: =CONCATENATE("INSERT INTO DOCUMENTOS (NRO_DOCUMENTO,FECHA_EMISION,TOTAL_BRUTO,TOTAL_NETO,TOTAL_IVA, ID_TIPO, RUT_EMPLEADO, ID_CLIENTE) VALUES(",B1571,",","TO_DATE('",C1571,"'",",'DD-MM-YYYY'),",F1571,",",G1571,",",H1571,",",I1571,",","'",D1571,"',",E1571,");") -> INSERT INTO DOCUMENTOS (NRO_DOCUMENTO,FECHA_EMISION,TOTAL_BRUTO,TOTAL_NETO,TOTAL_IVA, ID_TIPO, RUT_EMPLEADO, ID_CLIENTE) VALUES(12,TO_DATE('14-02-2025','DD-MM-YYYY'),51490,43268,8222,2,'14526149-K',203);
B1572: 13 | C1572: 20-02-2025 | D1572: 14526149-K | E1572: 180 | F1572: 7300 | G1572: 6135 | H1572: 1165 | I1572: 2 | J1572: =CONCATENATE("INSERT INTO DOCUMENTOS (NRO_DOCUMENTO,FECHA_EMISION,TOTAL_BRUTO,TOTAL_NETO,TOTAL_IVA, ID_TIPO, RUT_EMPLEADO, ID_CLIENTE) VALUES(",B1572,",","TO_DATE('",C1572,"'",",'DD-MM-YYYY'),",F1572,",",G1572,",",H1572,",",I1572,",","'",D1572,"',",E1572,");") -> INSERT INTO DOCUMENTOS (NRO_DOCUMENTO,FECHA_EMISION,TOTAL_BRUTO,TOTAL_NETO,TOTAL_IVA, ID_TIPO, RUT_EMPLEADO, ID_CLIENTE) VALUES(13,TO_DATE('20-02-2025','DD-MM-YYYY'),7300,6135,1165,2,'14526149-K',180);
... B1634: 75 | C1634: 16-09-2025 | D1634: 14526149-K | E1634: 203 | F1634: 63450 | G1634: 53320 | H1634: 10130 | I1634: 2 | J1634: =CONCATENATE("INSERT INTO DOCUMENTOS (NRO_DOCUMENTO,FECHA_EMISION,TOTAL_BRUTO,TOTAL_NETO,TOTAL_IVA, ID_TIPO, RUT_EMPLEADO, ID_CLIENTE) VALUES(",B1634,",","TO_DATE('",C1634,"'",",'DD-MM-YYYY'),",F1634,",",G1634,",",H1634,",",I1634,",","'",D1634,"',",E1634,");") -> INSERT INTO DOCUMENTOS (NRO_DOCUMENTO,FECHA_EMISION,TOTAL_BRUTO,TOTAL_NETO,TOTAL_IVA, ID_TIPO, RUT_EMPLEADO, ID_CLIENTE) VALUES(75,TO_DATE('16-09-2025','DD-MM-YYYY'),63450,53320,10130,2,'14526149-K',203);
A1635: Total general | F1635: 35929330 | G1635: 30193012 | H1635: 5736318 | J1635: COMMIT;

Sheet DETALLE_DOCUMENTOS
A1: Id_Tipo | B1: Nro_Documento | C1: Fecha_Emision | D1: Rut_Empleado | E1: Id_Cliente | F1: Id_Producto | G1: Cantidad | H1: Precio | I1: Valor Bruto | J1: Valor Neto | K1: Valor Iva | L1: Script
A2: 1 | B2: 1 | C2: 02-01-2025 | D2: 14526149-K | E2: 108 | F2: 329 | G2: 1 | H2: 5500 | I2: 5500 | J2: 4622 | K2: 878 | L2: =CONCATENATE("INSERT INTO DETALLES_DOCUMENTO(NRO_DOCUMENTO,ID_TIPO,ID_PRODUCTO,CANTIDAD,PRECIO,VALOR_BRUTO,VALOR_NETO,VALOR_IVA) VALUES(",B2,",",A2,",",F2,",",G2,",",H2,",",I2,",",J2,",",K2,");") -> INSERT INTO DETALLES_DOCUMENTO(NRO_DOCUMENTO,ID_TIPO,ID_PRODUCTO,CANTIDAD,PRECIO,VALOR_BRUTO,VALOR_NETO,VALOR_IVA) VALUES(1,1,329,1,5500,5500,4622,878);
A3: 1 | B3: 1 | C3: 02-01-2025 | D3: 14526149-K | E3: 108 | F3: 382 | G3: 1 | H3: 2600 | I3: 2600 | J3: 2185 | K3: 415 | L3: =CONCATENATE("INSERT INTO DETALLES_DOCUMENTO(NRO_DOCUMENTO,ID_TIPO,ID_PRODUCTO,CANTIDAD,PRECIO,VALOR_BRUTO,VALOR_NETO,VALOR_IVA) VALUES(",B3,",",A3,",",F3,",",G3,",",H3,",",I3,",",J3,",",K3,");") -> INSERT INTO DETALLES_DOCUMENTO(NRO_DOCUMENTO,ID_TIPO,ID_PRODUCTO,CANTIDAD,PRECIO,VALOR_BRUTO,VALOR_NETO,VALOR_IVA) VALUES(1,1,382,1,2600,2600,2185,415);
A4: 1 | B4: 1 | C4: 02-01-2025 | D4: 14526149-K | E4: 108 | F4: 191 | G4: 1 | H4: 2500 | I4: 2500 | J4: 2101 | K4: 399 | L4: =CONCATENATE("INSERT INTO DETALLES_DOCUMENTO(NRO_DOCUMENTO,ID_TIPO,ID_PRODUCTO,CANTIDAD,PRECIO,VALOR_BRUTO,VALOR_NETO,VALOR_IVA) VALUES(",B4,",",A4,",",F4,",",G4,",",H4,",",I4,",",J4,",",K4,");") -> INSERT INTO DETALLES_DOCUMENTO(NRO_DOCUMENTO,ID_TIPO,ID_PRODUCTO,CANTIDAD,PRECIO,VALOR_BRUTO,VALOR_NETO,VALOR_IVA) VALUES(1,1,191,1,2500,2500,2101,399);
A5: 1 | B5: 2 | C5: 02-01-2025 | D5: 14526149-K | E5: 110 | F5: 296 | G5: 2 | H5: 7000 | I5: 14000 | J5: 11765 | K5: 2235 | L5: =CONCATENATE("INSERT INTO DETALLES_DOCUMENTO(NRO_DOCUMENTO,ID_TIPO,ID_PRODUCTO,CANTIDAD,PRECIO,VALOR_BRUTO,VALOR_NETO,VALOR_IVA) VALUES(",B5,",",A5,",",F5,",",G5,",",H5,",",I5,",",J5,",",K5,");") -> INSERT INTO DETALLES_DOCUMENTO(NRO_DOCUMENTO,ID_TIPO,ID_PRODUCTO,CANTIDAD,PRECIO,VALOR_BRUTO,VALOR_NETO,VALOR_IVA) VALUES(2,1,296,2,7000,14000,11765,2235);
A6: 1 | B6: 3 | C6: 02-01-2025 | D6: 14526149-K | E6: 111 | F6: 230 | G6: 1 | H6: 15500 | I6: 15500 | J6: 13025 | K6: 2475 | L6: =CONCATENATE("INSERT INTO DETALLES_DOCUMENTO(NRO_DOCUMENTO,ID_TIPO,ID_PRODUCTO,CANTIDAD,PRECIO,VALOR_BRUTO,VALOR_NETO,VALOR_IVA) VALUES(",B6,",",A6,",",F6,",",G6,",",H6,",",I6,",",J6,",",K6,");") -> INSERT INTO DETALLES_DOCUMENTO(NRO_DOCUMENTO,ID_TIPO,ID_PRODUCTO,CANTIDAD,PRECIO,VALOR_BRUTO,VALOR_NETO,VALOR_IVA) VALUES(3,1,230,1,15500,15500,13025,2475);
A7: 1 | B7: 4 | C7: 02-01-2025 | D7: 14526149-K | E7: 116 | F7: 370 | G7: 1 | H7: 4000 | I7: 4000 | J7: 3361 | K7: 639 | L7: =CONCATENATE("INSERT INTO DETALLES_DOCUMENTO(NRO_DOCUMENTO,ID_TIPO,ID_PRODUCTO,CANTIDAD,PRECIO,VALOR_BRUTO,VALOR_NETO,VALOR_IVA) VALUES(",B7,",",A7,",",F7,",",G7,",",H7,",",I7,",",J7,",",K7,");") -> INSERT INTO DETALLES_DOCUMENTO(NRO_DOCUMENTO,ID_TIPO,ID_PRODUCTO,CANTIDAD,PRECIO,VALOR_BRUTO,VALOR_NETO,VALOR_IVA) VALUES(4,1,370,1,4000,4000,3361,639);
A8: 1 | B8: 4 | C8: 02-01-2025 | D8: 14526149-K | E8: 116 | F8: 383 | G8: 2 | H8: 4800 | I8: 9600 | J8: 8067 | K8: 1533 | L8: =CONCATENATE("INSERT INTO DETALLES_DOCUMENTO(NRO_DOCUMENTO,ID_TIPO,ID_PRODUCTO,CANTIDAD,PRECIO,VALOR_BRUTO,VALOR_NETO,VALOR_IVA) VALUES(",B8,",",A8,",",F8,",",G8,",",H8,",",I8,",",J8,",",K8,");") -> INSERT INTO DETALLES_DOCUMENTO(NRO_DOCUMENTO,ID_TIPO,ID_PRODUCTO,CANTIDAD,PRECIO,VALOR_BRUTO,VALOR_NETO,VALOR_IVA) VALUES(4,1,383,2,4800,9600,8067,1533);
A9: 1 | B9: 4 | C9: 02-01-2025 | D9: 14526149-K | E9: 116 | F9: 165 | G9: 1 | H9: 2000 | I9: 2000 | J9: 1681 | K9: 319 | L9: =CONCATENATE("INSERT INTO DETALLES_DOCUMENTO(NRO_DOCUMENTO,ID_TIPO,ID_PRODUCTO,CANTIDAD,PRECIO,VALOR_BRUTO,VALOR_NETO,VALOR_IVA) VALUES(",B9,",",A9,",",F9,",",G9,",",H9,",",I9,",",J9,",",K9,");") -> INSERT INTO DETALLES_DOCUMENTO(NRO_DOCUMENTO,ID_TIPO,ID_PRODUCTO,CANTIDAD,PRECIO,VALOR_BRUTO,VALOR_NETO,VALOR_IVA) VALUES(4,1,165,1,2000,2000,1681,319);
A10: 1 | B10: 4 | C10: 02-01-2025 | D10: 14526149-K | E10: 116 | F10: 157 | G10: 1 | H10: 4300 | I10: 4300 | J10: 3613 | K10: 687 | L10: =CONCATENATE("INSERT INTO DETALLES_DOCUMENTO(NRO_DOCUMENTO,ID_TIPO,ID_PRODUCTO,CANTIDAD,PRECIO,VALOR_BRUTO,VALOR_NETO,VALOR_IVA) VALUES(",B10,",",A10,",",F10,",",G10,",",H10,",",I10,",",J10,",",K10,");") -> INSERT INTO DETALLES_DOCUMENTO(NRO_DOCUMENTO,ID_TIPO,ID_PRODUCTO,CANTIDAD,PRECIO,VALOR_BRUTO,VALOR_NETO,VALOR_IVA) VALUES(4,1,157,1,4300,4300,3613,687);
A11: 1 | B11: 4 | C11: 02-01-2025 | D11: 14526149-K | E11: 116 | F11: 29 | G11: 1 | H11: 1000 | I11: 1000 | J11: 840 | K11: 160 | L11: =CONCATENATE("INSERT INTO DETALLES_DOCUMENTO(NRO_DOCUMENTO,ID_TIPO,ID_PRODUCTO,CANTIDAD,PRECIO,VALOR_BRUTO,VALOR_NETO,VALOR_IVA) VALUES(",B11,",",A11,",",F11,",",G11,",",H11,",",I11,",",J11,",",K11,");") -> INSERT INTO DETALLES_DOCUMENTO(NRO_DOCUMENTO,ID_TIPO,ID_PRODUCTO,CANTIDAD,PRECIO,VALOR_BRUTO,VALOR_NETO,VALOR_IVA) VALUES(4,1,29,1,1000,1000,840,160);
A12: 1 | B12: 5 | C12: 02-01-2025 | D12: 14526149-K | E12: 119 | F12: 329 | G12: 1 | H12: 5500 | I12: 5500 | J12: 4622 | K12: 878 | L12: =CONCATENATE("INSERT INTO DETALLES_DOCUMENTO(NRO_DOCUMENTO,ID_TIPO,ID_PRODUCTO,CANTIDAD,PRECIO,VALOR_BRUTO,VALOR_NETO,VALOR_IVA) VALUES(",B12,",",A12,",",F12,",",G12,",",H12,",",I12,",",J12,",",K12,");") -> INSERT INTO DETALLES_DOCUMENTO(NRO_DOCUMENTO,ID_TIPO,ID_PRODUCTO,CANTIDAD,PRECIO,VALOR_BRUTO,VALOR_NETO,VALOR_IVA) VALUES(5,1,329,1,5500,5500,4622,878);
